Workbook
Name ___r: #REF!
Name ___r: #REF!
Name ___r: #REF!
Name ___r: #REF!
Name __r: #REF!
Name __r: #REF!
Name __r: #REF!
Name __r: #REF!
Name _r: #REF!
Name _r: #REF!
Name _r: #REF!
Name _r: #REF!
Name _r: #REF!
Name _r: #REF!
Name _r: #REF!
Name _r: #REF!
Name _r: #REF!
Name _r: #REF!
Name _r: #REF!
Name _r: #REF!
Name _Regression_Int: 1
Name A_impresión_IM: #REF!
Name A_impresión_IM: #REF!
Name A_impresión_IM: #REF!
Name A_impresión_IM: #REF!
Name ActualBeyond: 'Control Producción'!PeriodInActual*(#REF!>0)
Name ActualBeyond: PeriodInActual*('[4]Planificador de proyectos'!$E1>0)
Name agno: #REF!
Name agno: [5]EstadoCAPEX!$C$1
Name AREA_DE_IMPRESI: #REF!
Name AREA_DE_IMPRESI: [6]hed99!$A$237:$S$275
Name avFísicoPROG: #REF!
Name avFísicoPROG: [5]ProyGANTT!$I$44
Name avFísicoREAL: #REF!
Name avFísicoREAL: [5]ProyGANTT!$J$44
Name b: #REF!
Name b: #REF!
Name b: #REF!
Name b: #REF!
Name b: #REF!
Name b: #REF!
Name b: #REF!
Name b: #REF!
Name b: #REF!
Name b: #REF!
Name b: #REF!
Name b: #REF!
Name b: #REF!
Name Bal: #REF!
Name Bal: #REF!
Name Bal: #REF!
Name Bal: #REF!
Name Bal: #REF!
Name Bal: #REF!
Name Bal: #REF!
Name Bal: #REF!
Name Bal: #REF!
Name Bal: #REF!
Name Bal: #REF!
Name Bal: #REF!

Sheet Factores
B2: Mes Actual : | D2: 46082.792
B3: Fecha Actualización: | D3: 46098.792 | E3: <- Poner la fecha dia anPerior en celda "D3".
D6: Deduccion Metalurgica (Bdgt) | E6: Deduccion Metalurgica | F6: Deduccion Metalurgica (real)
C7: Cu | D7: =+E7 -> 0.962 | E7: 0.962 | F7: 0.962
C8: Mo | D8: 0.995 | E8: 0.995 | F8: 0.995
C9: Relacion Mo/Cu | D9: 2.899 | E9: 2.899 | F9: 2.899
C12: Cu en CuCons | D12: Pagable Cu
C13: 15 | D13: 0.927
C14: 16 | D14: 0.931
C15: 17 | D15: 0.935
C16: 18 | D16: 0.939
C17: 19 | D17: 0.942
C18: 20 | D18: 0.945
C19: 21 | D19: 0.948
C20: 22 | D20: 0.95
C21: 23 | D21: 0.952
C22: 24 | D22: 0.958
C23: 25 | D23: 0.96
C24: 26 | D24: 0.962
... C39: 41 | D39: 0.968
C40: 42 | D40: 0.968 | AS40: =#N/A -> #N/A
C41: 43 | D41: 0.968
C42: 44 | D42: 0.968
C43: 45 | D43: 0.968

Sheet Comparacion (Sin BM)
B1: INFORME : | E1: B : BudgeP
B2: MES : | C2: =[16]FacPores!D2 -> #REF! | E2: F : Forecast | O2: DELTA INVENTARIO MES | Q2: R+P | R2: ST | T2: Q | V2: DELTA INVENTARIO MES | X2: REAL | Y2: S.T.
B3: Fecha Actualización: | C3: =[17]Hoja1!K3 -> 41623.792 | E3: S.T.: Short Term | O3: Cu Fino Filtrado | Q3: =+Q15/0.966 -> 27.335085 | R3: =+R15/0.966 -> 28.188194 | V3: Cu Fino Filtrado | X3: =Real!AQ40/1000 -> 13.096116 | Y3: ='ST Original'!GF37/1000 -> 0 | AK3: CuFFP Real vs ST
E4: P : Proyeccion | O4: Delta Inventario Cu | Q4: =+Q3-Q14 -> -0.02693531 | R4: =+R3-R14 -> -0.13015778 | T4: =+Q4-R4 -> 0.10322247 | V4: Delta Inventario Cu | X4: =+X3-X14 -> 0.12176294 | Y4: =+Y3-Y14 -> -13.540082 | AA4: =+X4-Y4 -> 13.661845 | AC4: CUMPLIMIENTO REAL vs ST ACUM. MES | AK4: Dias | AQ4: 0.966 | AV4: Dias | BE4: Dias | BK4: 0.995
E5: R : Real | O5: Mo Fin o Envasado | Q5: =+Q19/0.995 -> 1.0004937 | R5: =+R19/0.995 -> 0.88119476 | V5: Mo Fin o Envasado | X5: =Real!AA40/1000 -> 0.56844523 | Y5: ='ST Original'!GA37/1000 -> 0 | AC5: Dias | AK5: =AC6 -> 1 | AL5: TPH | AM5: CM | AN5: Ley Cu | AO5: Rec Cu | AP5: Inv | AQ5: FP | AR5: TMF | AS5: dif | AV5: =+AC6 -> 1 | AW5: TPH | AX5: CM | AY5: Ley Mo | AZ5: RMoCol, % | BA5: RMoSel, % | BB5: Mo Fino, ton | BC5: dif | BE5: =+AC6 -> 1 | BF5: TPH | BG5: CM | BH5: Ley Mo | BI5: RMoCol, % | BJ5: RMoSel, % | BK5: Inv | BL5: FP | BM5: TMF | BN5: dif
B6: Nota : Se usó valores de comercialización de | F6: =Factores!D3 -> 46098.792 | O6: Delta Inventario Mo | Q6: =+Q5-Q18 -> 0.092866388 | R6: =+R5-R18 -> 0.073248003 | T6: =+Q6-R6 -> 0.019618384 | V6: Delta Inventario Mo | X6: =+X5-X18 -> 0.073101146 | Y6: =+Y5-Y18 -> -0.45280369 | AA6: =+X6-Y6 -> 0.52590483 | AC6: 1 | AD6: TPH | AE6: CM | AF6: Ley Cu | AG6: Rec Cu | AH6: TMF | AI6: dif | AK6: ST | AL6: =+AD7 -> 8414.2412 | AM6: =+AE7 -> 88.216548 | AN6: =+AF7 -> 0.51107742 | AO6: =+AG7 -> 90.302073 | AP6: =+Y4*1000*AQ4 -> -13079.72 | AQ6: =+AR6*$AQ$4+AP6 -> -12285.505 | AR6: =+((AL6*24*AM6/100*$AC$6)*AN6*AO6)/10000 -> 822.1682 | AS6: =+AQ6 -> -12285.505 | AV6: ST | AW6: =+AD7 -> 8414.2412 | AX6: =+AE7 -> 88.216548 | AY6: =+Y39/10000 -> 0.019092613 | AZ6: =+Y41 -> 92.043617 | BA6: =+Y42 -> 87.824161 | BB6: =+((AW6*24*AX6/100*$AV$5)*AY6*AZ6*BA6)/1000000 -> 27.494721 | BC6: =+BB6 -> 27.494721 | BE6: ST | BF6: =+AD7 -> 8414.2412 | BG6: =+AE7 -> 88.216548 | BH6: =+Y39/10000 -> 0.019092613 | BI6: =+Y41 -> 92.043617 | BJ6: =+Y42 -> 87.824161 | BK6: =+Y6*1000 -> -452.80369 | BL6: =+BM6*$BK$4+BK6 -> -425.44644 | BM6: =+((BF6*24*BG6/100*$AC$6)*BH6*BI6*BJ6)/1000000 -> 27.494721 | BN6: =+BL6 -> -425.44644
AC7: ST | AD7: =+AF70 -> 8414.2412 | AE7: =+Y32 -> 88.216548 | AF7: =+Y34 -> 0.51107742 | AG7: =+Y35 -> 90.302073 | AH7: =+((AD7*24*AE7/100*$AC$6)*AF7*AG7)/10000 -> 822.1682 | AI7: =+AH7 -> 822.1682 | AK7: Rendimiento | AL7: =+$AD$24 -> 0 | AM7: =+AM6 -> 88.216548 | AN7: =+$AF$7 -> 0.51107742 | AO7: =+$AG$7 -> 90.302073 | AP7: =+AP6 -> -13079.72 | AQ7: =+AR7*$AQ$4+AP7 -> -13079.72 | AR7: =+((AL7*24*AM7/100*$AC$6)*AN7*AO7)/10000 -> 0 | AS7: =+AQ7-AQ6 -> -794.21448 | AV7: TPH | AW7: =+AW24 -> 0 | AX7: =+AX6 -> 88.216548 | AY7: =+AY6 -> 0.019092613 | AZ7: =+AZ6 -> 92.043617 | BA7: =+BA6 -> 87.824161 | BB7: =+((AW7*24*AX7/100*$AV$5)*AY7*AZ7*BA7)/1000000 -> 0 | BC7: =+BB7-BB6 -> -27.494721 | BE7: Rendimiento | BF7: =+BF13 -> 0 | BG7: =+BG6 -> 88.216548 | BH7: =+BH6 -> 0.019092613 | BI7: =+BI6 -> 92.043617 | BJ7: =+BJ6 -> 87.824161 | BK7: =+BK6 -> -452.80369 | BL7: =+BM7*$BK$4+BK7 -> -452.80369 | BM7: =+((BF7*24*BG7/100*$AC$6)*BH7*BI7*BJ7)/1000000 -> 0 | BN7: =+BL7-BL6 -> -27.357248
A8: COMPARACION SHORT TERM ORIGINAL VS BUDGET | H8: COMPARACION SHORT TERM ORIGINAL VS FORECAST | O8: COMPARACION REAL+PROYECCION VS SHORT TERM | V8: REAL VS SHORT TERM | AC8: Rendimiento | AD8: =+$AD$24 -> 0 | AE8: =+AE7 -> 88.216548 | AF8: =+$AF$7 -> 0.51107742 | AG8: =+$AG$7 -> 90.302073 | AH8: =+((AD8*24*AE8/100*$AC$6)*AF8*AG8)/10000 -> 0 | AI8: =+AH8-AH7 -> -822.1682 | AK8: C.M. | AL8: =+$AD$24 -> 0 | AM8: =+$AE$24 -> 0 | AN8: =+$AF$7 -> 0.51107742 | AO8: =+$AG$7 -> 90.302073 | AP8: =+AP6 -> -13079.72 | AQ8: =+AR8*$AQ$4+AP8 -> -13079.72 | AR8: =+((AL8*24*AM8/100*$AC$6)*AN8*AO8)/10000 -> 0 | AS8: =+AQ8-AQ7 -> 0 | AV8: CM | AW8: =+AW24 -> 0 | AX8: =+AX24 -> 0 | AY8: =+AY6 -> 0.019092613 | AZ8: =+AZ6 -> 92.043617 | BA8: =+BA6 -> 87.824161 | BB8: =+((AW8*24*AX8/100*$AV$5)*AY8*AZ8*BA8)/1000000 -> 0 | BC8: =+BB8-BB7 -> 0 | BE8: CM | BF8: =+BF13 -> 0 | BG8: =+BG13 -> 0 | BH8: =+BH6 -> 0.019092613 | BI8: =+BI6 -> 92.043617 | BJ8: =+BJ6 -> 87.824161 | BK8: =+BK6 -> -452.80369 | BL8: =+BM8*$BK$4+BK8 -> -452.80369 | BM8: =+((BF8*24*BG8/100*$AC$6)*BH8*BI8*BJ8)/1000000 -> 0 | BN8: =+BL8-BL7 -> 0
A9: PARA EL MES | B9: =C2 -> #REF! | E9: VARIACION | H9: PARA EL MES | I9: =C2 -> #REF! | L9: VARIACION | O9: PARA EL MES | P9: =C2 -> #REF! | S9: VARIACION | V9: PARA EL DIA | W9: =C2 -> #REF! | Z9: VARIACION | AC9: C.M. | AD9: =+$AD$24 -> 0 | AE9: =+$AE$24 -> 0 | AF9: =+$AF$7 -> 0.51107742 | AG9: =+$AG$7 -> 90.302073 | AH9: =+((AD9*24*AE9/100*$AC$6)*AF9*AG9)/10000 -> 0 | AI9: =+AH9-AH8 -> 0 | AK9: Ley Cab. Cu,% | AL9: =+$AD$24 -> 0 | AM9: =+$AE$24 -> 0 | AN9: =+$AF$24 -> 0 | AO9: =+$AG$7 -> 90.302073 | AP9: =+AP6 -> -13079.72 | AQ9: =+AR9*$AQ$4+AP9 -> -13079.72 | AR9: =+((AL9*24*AM9/100*$AC$6)*AN9*AO9)/10000 -> 0 | AS9: =+AQ9-AQ8 -> 0 | AV9: Ley Mo | AW9: =+AW24 -> 0 | AX9: =+AX24 -> 0 | AY9: =+AY24 -> 0 | AZ9: =+AZ6 -> 92.043617 | BA9: =+BA6 -> 87.824161 | BB9: =+((AW9*24*AX9/100*$AV$5)*AY9*AZ9*BA9)/1000000 -> 0 | BC9: =+BB9-BB8 -> 0 | BE9: Ley Mo | BF9: =+BF13 -> 0 | BG9: =+BG13 -> 0 | BH9: =+BH13 -> 0.020905586 | BI9: =+BI6 -> 92.043617 | BJ9: =+BJ6 -> 87.824161 | BK9: =+BK6 -> -452.80369 | BL9: =+BM9*$BK$4+BK9 -> -452.80369 | BM9: =+((BF9*24*BG9/100*$AC$6)*BH9*BI9*BJ9)/1000000 -> 0 | BN9: =+BL9-BL8 -> 0
B10: UNIDAD | C10: S.T. | D10: B | E10: Q | F10: % | I10: UNIDAD | J10: S.T. | K10: F | L10: Q | M10: % | P10: UNIDAD | Q10: R+P | R10: S.T. | S10: Q | T10: % | W10: UNIDAD | X10: REAL | Y10: S.T. | Z10: Q | AA10: % | AC10: Ley Cab. Cu,% | AD10: =+$AD$24 -> 0 | AE10: =+$AE$24 -> 0 | AF10: =+$AF$24 -> 0 | AG10: =+$AG$7 -> 90.302073 | AH10: =+((AD10*24*AE10/100*$AC$6)*AF10*AG10)/10000 -> 0 | AI10: =+AH10-AH9 -> 0 | AK10: RCu, % | AL10: =+$AD$24 -> 0 | AM10: =+$AE$24 -> 0 | AN10: =+$AF$24 -> 0 | AO10: =+$AG$24 -> 0 | AP10: =+AP6 -> -13079.72 | AQ10: =+AR10*$AQ$4+AP10 -> -13079.72 | AR10: =+((AL10*24*AM10/100*$AC$6)*AN10*AO10)/10000 -> 0 | AS10: =+AQ10-AQ9 -> 0 | AV10: RMoCol, % | AW10: =+AW24 -> 0 | AX10: =+AX24 -> 0 | AY10: =+AY24 -> 0 | AZ10: =+AZ24 -> 0 | BA10: =+BA9 -> 87.824161 | BB10: =+((AW10*24*AX10/100*$AV$5)*AY10*AZ10*BA10)/1000000 -> 0 | BC10: =+BB10-BB9 -> 0 | BE10: RMoCol, % | BF10: =+BF13 -> 0 | BG10: =+BG13 -> 0 | BH10: =+BH13 -> 0.020905586 | BI10: =+BI13 -> 89.313167 | BJ10: =+BJ9 -> 87.824161 | BK10: =+BK6 -> -452.80369 | BL10: =+BM10*$BK$4+BK10 -> -452.80369 | BM10: =+((BF10*24*BG10/100*$AC$6)*BH10*BI10*BJ10)/1000000 -> 0 | BN10: =+BL10-BL9 -> 0
A11: Cu Fino Eq. Producido | B11: Kton | C11: ='ST Original'!#REF!/1000 -> #REF! | D11: =+BDGT!H7+BDGT!H9*BDGT!$H$60 -> 22.933613 | E11: =+C11-D11 -> #REF! | F11: =+E11/D11 -> #REF! | H11: Cu Fino Eq. Producido | I11: Kton | J11: =C11 -> #REF! | K11: ='ST Original'!#REF!/1000 -> #REF! | L11: =+J11-K11 -> #REF! | M11: =+L11/K11 -> #REF! | O11: Cu Fino Eq. Producido | P11: Kton | Q11: ='R+P'!AF39/1000 -> 29.993232 | R11: =C11 -> #REF! | S11: =+Q11-R11 -> #REF! | T11: =+S11/R11 -> #REF! | V11: Cu Fino Eq. Producido | W11: Kton | X11: =+Real!Q40/1000 -> 12.974353 | Y11: =C11 -> #REF! | Z11: =+X11-Y11 -> #REF! | AA11: =+Z11/Y11 -> #REF! | AC11: RCu, % | AD11: =+$AD$24 -> 0 | AE11: =+$AE$24 -> 0 | AF11: =+$AF$24 -> 0 | AG11: =+$AG$24 -> 0 | AH11: =+((AD11*24*AE11/100*$AC$6)*AF11*AG11)/10000 -> 0 | AI11: =+AH11-AH10 -> 0 | AK11: Inv | AL11: =+$AD$24 -> 0 | AM11: =+$AE$24 -> 0 | AN11: =+$AF$24 -> 0 | AO11: =+$AG$24 -> 0 | AP11: =+X4*1000*AQ4 -> 117.623 | AQ11: =+AR11*$AQ$4+AP11 -> 117.623 | AR11: =+((AL11*24*AM11/100*$AC$6)*AN11*AO11)/10000 -> 0 | AS11: =+AQ11-AQ10 -> 13197.343 | AV11: RMoSel, % | AW11: =+AW10 -> 0 | AX11: =+AX10 -> 0 | AY11: =+AY10 -> 0 | AZ11: =+AZ10 -> 0 | BA11: =+BA24 -> 0 | BB11: =+((AW11*24*AX11/100*$AV$5)*AY11*AZ11*BA11)/1000000 -> 0 | BC11: =+BB11-BB10 -> 0 | BE11: RMoSel, % | BF11: =+BF13 -> 0 | BG11: =+BG13 -> 0 | BH11: =+BH13 -> 0.020905586 | BI11: =+BI13 -> 89.313167 | BJ11: =+BJ13 -> 90.883109 | BK11: =+BK6 -> -452.80369 | BL11: =+BM11*$BK$4+BK11 -> -452.80369 | BM11: =+((BF11*24*BG11/100*$AC$6)*BH11*BI11*BJ11)/1000000 -> 0 | BN11: =+BL11-BL10 -> 0
A12: Cu Fino Eq. Filtrado (Ppto) | B12: Kton | C12: =C15+C19*Factores!$D$9 -> 29.771606 | D12: =D15+D19*Factores!$D$9 -> 33.406194 | E12: =+C24-D24 -> 0 | F12: =+E24/D24 -> #DIV/0! | H12: Cu Fino Eq. Filtrado (Ppto) | I12: Kton | J12: =C24 -> 0 | K12: =K15+K19*Factores!$D$9 -> #REF! | L12: =+J24-K24 -> 0 | M12: =+L24/K24 -> #DIV/0! | O12: Cu Fino Eq. Filtrado (Bdgt) | P12: Kton | Q12: =Q15+Q19*Factores!$D$9 -> 29.291621 | R12: =R15+R19*Factores!$D$9 -> 29.771606 | S12: =+Q24-R24 -> -25.560003 | T12: =+S24/R24 -> -0.11618183 | V12: Cu Fino Eq. Filtrado | W12: Kton | X12: =X15+X19*Factores!$D$9 -> 14.238147 | Y12: =C24 -> 0 | Z12: =+X24-Y24 -> 169.20919 | AA12: =+Z24/Y24 -> #DIV/0! | AC12: Real | AD12: =+AE70 -> 8365.4531 | AE12: =+X32 -> 88.117328 | AF12: =+X34 -> 0.49046726 | AG12: =+X35 -> 90.621182 | AH12: =+((AD24*24*AE24/100*$AC$6)*AF24*AG24)/10000 -> 0 | AI12: =SUM(AI7:AI11) -> 0 | AK12: Real | AL12: =+AD24 -> 0 | AM12: =+AE24 -> 0 | AN12: =+AF24 -> 0 | AO12: =+AG24 -> 0 | AP12: 1020 | AQ12: =+AR24*$AQ$4+AP24 -> 0 | AR12: =+((AL24*24*AM24/100*$AC$6)*AN24*AO24)/10000 -> 0 | AS12: =SUM(AS6:AS11) -> 117.623 | AV12: Real | AW12: =+AD24 -> 0 | AX12: =+AE24 -> 0 | AY12: =+X39/10000 -> 0.020905586 | AZ12: =+X41 -> 89.313167 | BA12: =+X42 -> 90.883109 | BB12: =+((AW24*24*AX24/100*$AV$5)*AY24*AZ24*BA24)/1000000 -> 0 | BC12: =SUM(BC6:BC11) -> 0 | BE12: Inv | BF12: =+BF13 -> 0 | BG12: =+BG13 -> 0 | BH12: =+BH13 -> 0.020905586 | BI12: =+BI13 -> 89.313167 | BJ12: =+BJ13 -> 90.883109 | BK12: =+X6*1000 -> 73.101146 | BL12: =+BM24*$BK$4+BK24 -> 0 | BM12: =+((BF24*24*BG24/100*$AC$6)*BH24*BI24*BJ24)/1000000 -> 0 | BN12: =+BL24-BL11 -> 452.80369
A13: Cu Fino Eq. Filtrado (Real) | B13: Kton | C13: =C16+C20*Factores!$F$9 -> 29.771606 | D13: =D16+D20*Factores!$F$9 -> 33.406194 | E13: =+C13-D13 -> -3.6345876 | F13: =+E13/D13 -> -0.10879981 | H13: Cu Fino Eq. Filtrado (Real) | I13: Kton | J13: =J16+J20*Factores!$F$9 -> 27.229795 | K13: =K16+K20*Factores!$F$9 -> #REF! | L13: =+J13-K13 -> #REF! | M13: =+L13/K13 -> #REF! | O13: Cu Fino Eq. Filtrado (Real) | P13: Kton | Q13: =Q16+Q20*Factores!$F$9 -> 29.291621 | R13: =R16+R20*Factores!$F$9 -> 29.771606 | S13: =+Q13-R13 -> -0.47998473 | T13: =+S13/R13 -> -0.016122232 | V13: Cu Fino Eq. Filtrado | W13: Kton | X13: =X16+X20*Factores!$F$9 -> 14.238147 | Y13: =C13 -> 29.771606 | Z13: =+X13-Y13 -> -15.533459 | AA13: =+Z13/Y13 -> -0.52175415 | BE13: Real | BF13: =+AD24 -> 0 | BG13: =+AE24 -> 0 | BH13: =+X39/10000 -> 0.020905586 | BI13: =+X41 -> 89.313167 | BJ13: =+X42 -> 90.883109 | BK13: =+BK24 -> 0 | BL13: =+BM13*$BK$4+BK13 -> 0 | BM13: =+((BF13*24*BG13/100*$AC$6)*BH13*BI13*BJ13)/1000000 -> 0
A14: Cu Fino Producido | B14: Kton | C14: =+'ST Original'!V39/1000 -> 28.318352 | D14: =+BDGT!H7 -> 22.933613 | E14: =+C14-D14 -> 5.3847386 | F14: =+E14/D14 -> 0.23479678 | H14: Cu Fino Producido | I14: Kton | J14: =C14 -> 28.318352 | K14: ='ST Original'!#REF!/1000 -> #REF! | L14: =+J14-K14 -> #REF! | M14: =+L14/K14 -> #REF! | O14: Cu Fino Producido | P14: Kton | Q14: ='R+P'!R47/1000 -> 27.36202 | R14: =C14 -> 28.318352 | S14: =+Q14-R14 -> -0.95633141 | T14: =+S14/R14 -> -0.03377073 | V14: Cu Fino Producido | W14: Kton | X14: =Real!$P$40/1000 -> 12.974353 | Y14: ='ST Original'!FQ39/1000 -> 13.540082 | Z14: =+X14-Y14 -> -0.56572901 | AA14: =+Z14/Y14 -> -0.0417818
A15: Cu Fino Filtrado Pagable (Ppto) | B15: Kton | C15: =+'ST Original'!AW39/1000 -> 27.229795 | D15: =+BDGT!J8 -> 31.316639 | E15: =+C15-D15 -> -4.0868432 | F15: =+E15/D15 -> -0.1305007 | H15: Cu Fino Filtrado Pagable (Ppto) | I15: Kton | J15: =C15 -> 27.229795 | K15: ='ST Original'!#REF!/1000*Factores!D7 -> #REF! | L15: =+J15-K15 -> #REF! | M15: =+L15/K15 -> #REF! | O15: Cu Fino Filtrado Pagable (Bdgt) | P15: Kton | Q15: ='R+P'!AO39*Factores!$D$7/1000 -> 26.405692 | R15: =C15 -> 27.229795 | S15: =+Q15-R15 -> -0.82410323 | T15: =+S15/R15 -> -0.03026476 | V15: Cu Fino Filtrado Pagable | W15: Kton | X15: =Real!AQ40*Factores!F7/1000 -> 12.598464 | Y15: ='ST Original'!$GF$39/1000*Factores!D7 -> 12.114235 | Z15: =+X15-Y15 -> 0.48422847 | AA15: =+Z15/Y15 -> 0.039971856
A16: Cu Fino Filtrado Pagable (Real) | B16: Kton | C16: =C15 -> 27.229795 | D16: =D15/Factores!$D$7*Factores!$F$7 -> 31.316639 | E16: =+C16-D16 -> -4.0868432 | F16: =+E16/D16 -> -0.1305007 | H16: Cu Fino Filtrado Pagable (Real) | I16: Kton | J16: =J15/Factores!$D$7*Factores!$F$7 -> 27.229795 | K16: =K15/Factores!$D$7*Factores!$F$7 -> #REF! | L16: =+J16-K16 -> #REF! | M16: =+L16/K16 -> #REF! | O16: Cu Fino Filtrado Pagable (Real) | P16: Kton | Q16: =Q15/Factores!$D$7*Factores!$F$7 -> 26.405692 | R16: =R15/Factores!$D$7*Factores!$F$7 -> 27.229795 | S16: =+Q16-R16 -> -0.82410323 | T16: =+S16/R16 -> -0.03026476 | V16: Cu Fino Filtrado pagable real | W16: Kton | X16: =X15/Factores!$D$7*Factores!$F$7 -> 12.598464 | Y16: ='ST Original'!$GF$39/1000*Factores!F7 -> 12.114235 | Z16: =+X16-Y16 -> 0.48422847 | AA16: =+Z16/Y16 -> 0.039971856
A17: Delta Inventario Cu Fino | B17: Kton | H17: Delta Inventario Cu Fino | I17: Kton | O17: Delta Inventario Cu Fino | P17: Kton | Q17: =Q14-Q15/Factores!D7 -> -0.086724087 | V17: Delta Inventario Cu Fino | W17: Kton | X17: =X14-X15/Factores!D7 -> -0.12176294 | Y17: =Y14-Y15/Factores!D7 -> 0.94732206
A18: Mo Fino Producido | B18: Kton | C18: ='ST Original'!AF39/1000 -> 0.80794675 | D18: =+BDGT!H9 -> 0.49377314 | E18: =+C18-D18 -> 0.31417361 | F18: =+E18/D18 -> 0.63627117 | H18: Mo Fino Producido | I18: Kton | J18: =C18 -> 0.80794675 | K18: ='ST Original'!#REF!/1000 -> #REF! | L18: =+J18-K18 -> #REF! | M18: =+L18/K18 -> #REF! | O18: Mo Fino Producido | P18: Kton | Q18: ='R+P'!AA39/1000 -> 0.90762735 | R18: =C18 -> 0.80794675 | S18: =+Q18-R18 -> 0.099680594 | T18: =+S18/R18 -> 0.1233752 | V18: Mo Fino Producido | W18: Kton | X18: =Real!$Y$40/1000 -> 0.49534409 | Y18: ='ST Original'!FY39/1000 -> 0.45280369 | Z18: =+X18-Y18 -> 0.042540401 | AA18: =+Z18/Y18 -> 0.093948884
A19: Mo Fino Envasado Pagable (Ppto) | B19: Kton | C19: ='ST Original'!AG39/1000*Factores!$D$8 -> 0.87678878 | D19: =+BDGT!J10 -> 0.72078476 | E19: =+C19-D19 -> 0.15600402 | F19: =+E19/D19 -> 0.21643635 | H19: Mo Fino Envasado Pagable (Ppto) | I19: Kton | K19: ='ST Original'!#REF!/1000*Factores!D8 -> #REF! | L19: =+J19-K19 -> #REF! | M19: =+L19/K19 -> #REF! | O19: Mo Fino Envasado Pagable (Bdgt) | P19: Kton | Q19: ='R+P'!AC39/1000*Factores!$D$8 -> 0.99549127 | R19: =C19 -> 0.87678878 | S19: =+Q19-R19 -> 0.11870248 | T19: =+S19/R19 -> 0.13538321 | V19: Mo Fino Envasado Pagable (Bdgt) | W19: Kton | X19: =Real!AA40/1000*Factores!$D$8 -> 0.56560301 | Y19: ='ST Original'!GA39/1000*Factores!D8 -> 0.44690052 | Z19: =+X19-Y19 -> 0.11870248 | AA19: =+Z19/Y19 -> 0.26561276
A20: Mo Fino Envasado Pagable (Real) | B20: Kton | C20: =C19/Factores!$D$8*Factores!$F$8 -> 0.87678878 | D20: =D19/Factores!$D$8*Factores!$F$8 -> 0.72078476 | E20: =+C20-D20 -> 0.15600402 | F20: =+E20/D20 -> 0.21643635 | H20: Mo Fino Envasado Pagable (Real) | I20: Kton | J20: =J19/Factores!$D$8*Factores!$F$8 -> 0 | K20: =K19/Factores!$D$8*Factores!$F$8 -> #REF! | L20: =+J20-K20 -> #REF! | M20: =+L20/K20 -> #REF! | O20: Mo Fino Envasado Pagable (Real) | P20: Kton | Q20: =Q19/Factores!$D$8*Factores!$F$8 -> 0.99549127 | R20: =R19/Factores!$D$8*Factores!$F$8 -> 0.87678878 | S20: =+Q20-R20 -> 0.11870248 | T20: =+S20/R20 -> 0.13538321 | V20: Mo Fino Envasado Pagable (Real) | W20: Kton | X20: =X19/Factores!$D$8*Factores!$F$8 -> 0.56560301 | Y20: ='ST Original'!GA39/1000*Factores!F8 -> 0.44690052 | Z20: =+X20-Y20 -> 0.11870248 | AA20: =+Z20/Y20 -> 0.26561276
A21: Delta Inventario Mo Fino | B21: Kton | H21: Delta Inventario Mo Fino | I21: Kton | O21: Delta Inventario Mo Fino | P21: Kton | Q21: =Q18-Q19/Factores!D8 -> -0.092866388 | V21: Delta Inventario Mo Fino | W21: Kton | X21: =X18-X19/Factores!D8 -> -0.073101146 | Y21: =C21 -> 0 | AC21: Deducción Metalúrgica del Mo | AD21: =Factores!#REF! -> #REF!
O22: Stockpile Fin de Mes | P22: Kton | Q22: =+'R+P'!#REF!/1000 -> #REF! | R22: =+'ST Original'!#REF!/1000 -> #REF! | S22: =+Q22-R22 -> #REF! | T22: =+S22/R22 -> #REF! | Y22: =C22 -> 0
O23: Tonelaje Enviado STMG | P23: Kton | Q23: ='R+P'!D39/1000 -> 6027.6399 | R23: ='ST Original'!D37/1000 -> 672.09613 | S23: =+Q23-R23 -> 5355.5438 | T23: =+S23/R23 -> 7.9684193 | V23: Tonelaje Enviado STMG | W23: Kton | X23: =Real!D40/1000 -> 2876.5563 | Y23: =C23 -> 0 | Z23: =+X23-Y23 -> 2876.5563 | AA23: =+Z23/Y23 -> #DIV/0!
O24: Toneladas enviado STMG por día | P24: Ktpd | Q24: ='R+P'!C39/1000 -> 194.44 | R24: ='ST Original'!C37/1000 -> 220 | S24: =+Q24-R24 -> -25.560003 | T24: =+S24/R24 -> -0.11618183 | V24: Toneladas enviado STMG por día | W24: Ktpd | X24: =Real!C40/1000 -> 169.20919 | Y24: =C24 -> 0 | Z24: =+X24-Y24 -> 169.20919 | AA24: =+Z24/Y24 -> #DIV/0!
A26: Extracción | B26: Kton | C26: ='ST Original'!#REF! -> #REF! | D26: ='ST Original'!#REF! -> #REF! | E26: =+C26-D26 -> #REF! | F26: =+E26/D26 -> #REF! | H26: Extracción | I26: Kton | J26: =C26 -> #REF! | K26: ='ST Original'!#REF! -> #REF! | L26: =+J26-K26 -> #REF! | M26: =+L26/K26 -> #REF! | O26: Extracción | P26: Kton | Q26: ='R+P'!#REF!/1000 -> #REF! | R26: =C26 -> #REF! | S26: =+Q26-R26 -> #REF! | T26: =+S26/R26 -> #REF! | V26: Extracción | W26: Kton | X26: =Real!$AW$40/1000 -> 7028.6855 | Y26: ='ST Original'!#REF!/1000 -> #REF! | Z26: =+X26-Y26 -> #REF! | AA26: =+Z26/Y26 -> #REF!
A27: Tonelaje Procesado | B27: Kton | C27: =+'ST Original'!E39/1000 -> 5857.1988 | D27: ='ST Original'!#REF! -> #REF! | E27: =+C27-D27 -> #REF! | F27: =+E27/D27 -> #REF! | H27: Tonelaje Procesado | I27: Kton | J27: =C27 -> 5857.1988 | K27: ='ST Original'!#REF! -> #REF! | L27: =+J27-K27 -> #REF! | M27: =+L27/K27 -> #REF! | O27: Tonelaje Procesado | P27: Kton | Q27: =+'R+P'!E47 -> 5834.851 | R27: =C27 -> 5857.1988 | S27: =+Q27-R27 -> -22.347735 | T27: =+S27/R27 -> -0.0038154305 | V27: Tonelaje Procesado | W27: Kton | X27: =Real!$F$40/1000 -> 2919.0798 | Y27: ='ST Original'!$FG$39/1000 -> 2933.8431 | Z27: =+X27-Y27 -> -14.763304 | AA27: =+Z27/Y27 -> -0.0050320699
A28: Toneladas por día | B28: Ktpd | C28: ='ST Original'!E39/COUNT('ST Original'!B8:B38)/1000 -> 188.9419 | D28: ='ST Original'!#REF!/COUNT('ST Original'!B8:B36) -> #REF! | E28: =+C28-D28 -> #REF! | F28: =+E28/D28 -> #REF! | H28: Toneladas por día | I28: Ktpd | J28: =C28 -> 188.9419 | K28: ='ST Original'!#REF!/COUNT('ST Original'!B8:B36) -> #REF! | L28: =+J28-K28 -> #REF! | M28: =+L28/K28 -> #REF! | O28: Toneladas por día | P28: Ktpd | Q28: ='R+P'!E39/COUNT('R+P'!B8:B38)/1000 -> 188.221 | R28: =C28 -> 188.9419 | S28: =+Q28-R28 -> -0.72089467 | T28: =+S28/R28 -> -0.0038154305 | V28: Toneladas por día | W28: Ktpd | X28: =Real!$E$40/1000 -> 2919.0798 | Y28: ='ST Original'!$FF$39/1000 -> 172.57901 | Z28: =+X28-Y28 -> 2746.5008 | AA28: =+Z28/Y28 -> 15.914455
A29: Rendimiento | B29: Tph | C29: =+'ST Original'!BT39 -> 8502.7682 | D29: ='ST Original'!#REF!*1000/(24*COUNT('ST Original'!B8:B38)*D32/100) -> #REF! | E29: =+C29-D29 -> #REF! | F29: =+E29/D29 -> #REF! | H29: Rendimiento | I29: Tph | J29: =C29 -> 8502.7682 | K29: =IF(ISNUMBER('ST Original'!#REF!*1000/(24*COUNT('ST Original'!B8:B36)*'ST Original'!#REF!/100)),'ST Original'!#REF!*1000/(24*COUNT('ST Original'!B8:B36)*'ST Original'!#REF!/100)," ") | L29: =IF(ISNUMBER(J29-K29),J29-K29," ") | M29: =+L29/K29 -> #VALUE! | O29: Rendimiento | P29: Tph | Q29: ='R+P'!BH39 -> 8494.565 | R29: =C29 -> 8502.7682 | S29: =+Q29-R29 -> -8.2032069 | T29: =+S29/R29 -> -0.00096476897 | V29: Rendimiento | W29: Tph | X29: =X27/(24*COUNT(Real!C9:C39))/X32% -> 8.1194104 | Y29: ='ST Original'!$FI$39 -> 8414.2412 | Z29: =+X29-Y29 -> -8406.1217 | AA29: =+Z29/Y29 -> -0.99903504
A30: Mineral Duro | B30: % | C30: ='ST Original'!K39 -> 73.985882 | D30: ='ST Original'!#REF! -> #REF! | E30: =+C30-D30 -> #REF! | F30: =+E30/D30 -> #REF! | H30: Mineral Duro | I30: % | J30: =C30 -> 73.985882 | K30: ='ST Original'!#REF! -> #REF! | L30: =+J30-K30 -> #REF! | M30: =+L30/K30 -> #REF! | O30: Mineral Duro | P30: % | Q30: ='R+P'!K39 -> 67.341178 | R30: =C30 -> 73.985882 | S30: =+R30-Q30 -> 6.6447044 | T30: =+S30/R30 -> 0.089810437 | V30: Mineral Duro | W30: % | X30: =Real!AD40 -> 62.153208 | Y30: ='ST Original'!$FJ$39 -> 73.498171 | Z30: =+X30-Y30 -> -11.344963 | AA30: =+Z30/Y30 -> -0.15435708
A31: F80 | B31: % | C31: =+'ST Original'!AX39 -> 4.2028666 | D31: ='ST Original'!#REF! -> #REF! | E31: =+C31-D31 -> #REF! | F31: =+E31/D31 -> #REF! | O31: F80 | P31: % | Q31: ='R+P'!BD39 -> 4.4644232 | R31: =C31 -> 4.2028666 | S31: =+R31-Q31 -> -0.26155667 | T31: =+S31/R31 -> -0.062232922 | V31: F80 | W31: In | X31: =+Real!AS40 -> 4.6902586 | Y31: ='ST Original'!$FA$39 -> 4.1675369 | Z31: =+X31-Y31 -> 0.5227217 | AA31: =+Z31/Y31 -> 0.12542701
A32: Coeficiente de Marcha | B32: % | C32: ='ST Original'!J39 -> 92.650689 | D32: ='ST Original'!#REF! -> #REF! | E32: =+C32-D32 -> #REF! | F32: =+E32/D32 -> #REF! | H32: Coeficiente de Marcha | I32: % | J32: =C32 -> 92.650689 | K32: ='ST Original'!#REF! -> #REF! | L32: =+J32-K32 -> #REF! | M32: =+L32/K32 -> #REF! | O32: Coeficiente de Marcha | P32: % | Q32: ='R+P'!J39 -> 92.32423 | R32: =C32 -> 92.650689 | S32: =+Q32-R32 -> -0.32645839 | T32: =+S32/R32 -> -0.0035235398 | V32: Coeficiente de Marcha | W32: % | X32: =Real!J40 -> 88.117328 | Y32: ='ST Original'!$FH$39 -> 88.216548 | Z32: =+X32-Y32 -> -0.099220776 | AA32: =+Z32/Y32 -> -0.0011247411
A33: AxB | B33: ton/kwh | C33: =+'ST Original'!AT39 -> 37.368349 | D33: =+'ST Original'!#REF! -> #REF! | E33: =+C33-D33 -> #REF! | F33: =+E33/D33 -> #REF! | O33: Axb | P33: ton/kwh | Q33: =+'R+P'!BE39 -> 37.97411 | R33: =C33 -> 37.368349 | S33: =+R33-Q33 -> -0.6057616 | T33: =+S33/R33 -> -0.016210553 | V33: AxB | W33: % | X33: =Real!AU40 -> 37.942958 | Y33: ='ST Original'!$GU$39 -> 36.900097 | Z33: =+X33-Y33 -> 1.0428608 | AA33: =+Z33/Y33 -> 0.028261735
A34: Ley Alim. Cu | B34: % | C34: =+'ST Original'!L39 -> 0.53544933 | D34: ='ST Original'!#REF! -> #REF! | E34: =+C34-D34 -> #REF! | F34: =+E34/D34 -> #REF! | H34: Ley Alim. Cu | I34: % | J34: =C34 -> 0.53544933 | K34: ='ST Original'!#REF! -> #REF! | L34: =+J34-K34 -> #REF! | M34: =+L34/K34 -> #REF! | O34: Ley Alim. Cu | P34: % | Q34: ='R+P'!$L$47 -> 0.51875622 | R34: =C34 -> 0.53544933 | S34: =+Q34-R34 -> -0.016693109 | T34: =+S34/R34 -> -0.03117589 | V34: Ley Alim. Cu | W34: % | X34: =Real!K40 -> 0.49046726 | Y34: ='ST Original'!$FK$39 -> 0.51107742 | Z34: =+X34-Y34 -> -0.020610154 | AA34: =+Z34/Y34 -> -0.040326872
A35: Rec. Cu | B35: % | C35: ='ST Original'!M39 -> 90.294153 | D35: ='ST Original'!#REF! -> #REF! | E35: =+C35-D35 -> #REF! | F35: =+E35/D35 -> #REF! | H35: Rec. Cu | I35: % | J35: =C35 -> 90.294153 | K35: ='ST Original'!#REF! -> #REF! | L35: =+J35-K35 -> #REF! | M35: =+L35/K35 -> #REF! | O35: Rec. Cu | P35: % | Q35: ='R+P'!$M$47 -> 90.397219 | R35: =C35 -> 90.294153 | S35: =+Q35-R35 -> 0.10306589 | T35: =+S35/R35 -> 0.0011414459 | V35: Rec. Cu | W35: % | X35: =Real!L40 -> 90.621182 | Y35: ='ST Original'!$FL$39 -> 90.302073 | Z35: =+X35-Y35 -> 0.31910823 | AA35: =+Z35/Y35 -> 0.0035337863 | AC35: Cu Fino Producido R+P vs ST | AQ35: 0.966 | AV35: Dias | BE35: Dias | BK35: =+Factores!F8 -> 0.995
A36: Conc Cu Producido | B36: Kton | C36: ='ST Original'!R39/1000 -> 105.75347 | D36: ='ST Original'!#REF!/1000 -> #REF! | E36: =+C36-D36 -> #REF! | F36: =+E36/D36 -> #REF! | H36: Conc Cu Producido | I36: Kton | J36: =C36 -> 105.75347 | K36: ='ST Original'!#REF!/1000 -> #REF! | L36: =+J36-K36 -> #REF! | M36: =+L36/K36 -> #REF! | O36: Conc Cu Producido | P36: Kton | Q36: ='R+P'!$P$47/1000 -> 103.61851 | R36: =C36 -> 105.75347 | S36: =+Q36-R36 -> -2.1349564 | T36: =+S36/R36 -> -0.020188051 | V36: Conc Cu Producido | W36: Kton | X36: =Real!N40/1000 -> 50.032932 | Y36: ='ST Original'!$FN$39/1000 -> 51.308583 | Z36: =+X36-Y36 -> -1.2756513 | AA36: =+Z36/Y36 -> -0.024862337 | AK36: =AC6 -> 1 | AL36: TPH | AM36: CM | AN36: Ley Cu | AO36: Rec Cu | AP36: Inv | AQ36: FP | AR36: TMF | AS36: dif | AV36: =AC6 -> 1 | AW36: TPH | AX36: CM | AY36: Ley Mo | AZ36: RMoCol, % | BA36: RMoSel, % | BB36: Mo Fino, ton | BC36: dif | BE36: =AC6 -> 1 | BF36: TPH | BG36: CM | BH36: Ley Mo | BI36: RMoCol, % | BJ36: RMoSel, % | BK36: Inv | BL36: FP | BM36: TMF | BN36: dif
A37: Ley Conc. Cu | B37: % | C37: ='ST Original'!N39 -> 26.777705 | D37: ='ST Original'!N39 -> 26.777705 | E37: =+C37-D37 -> 0 | F37: =+E37/D37 -> 0 | H37: Ley Conc. Cu | I37: % | J37: =C37 -> 26.777705 | K37: ='ST Original'!#REF! -> #REF! | L37: =+J37-K37 -> #REF! | M37: =+L37/K37 -> #REF! | O37: Ley Conc. Cu | P37: % | Q37: ='R+P'!$N$47 -> 26.406498 | R37: =C37 -> 26.777705 | S37: =+Q37-R37 -> -0.37120691 | T37: =+S37/R37 -> -0.013862536 | V37: Ley Conc. Cu | W37: % | X37: =Real!M40 -> 25.931627 | Y37: ='ST Original'!$FM$39 -> 26.389507 | Z37: =+X37-Y37 -> -0.45788027 | AA37: =+Z37/Y37 -> -0.017350846 | AC37: 10.5 | AD37: TPH | AE37: CM | AF37: Ley Cu | AG37: Rec Cu | AH37: TMF | AI37: dif | AK37: ST | AL37: =+AD38 -> 8502.7682 | AM37: =+AE38 -> 92.650689 | AN37: =+AF38 -> 0.53544933 | AO37: =+AG38 -> 90.294153 | AP37: =+R4*1000*AQ35 -> -125.73242 | AQ37: =+AR37*$AQ$4+AP37 -> 9146.0806 | AR37: =+((AL37*24*AM37/100*$AC$37)*AN37*AO37)/10000 -> 9598.1501 | AS37: =+AQ37 -> 9146.0806 | AV37: ST | AW37: =+AD38 -> 8502.7682 | AX37: =+AE38 -> 92.650689 | AY37: =+R39/10000 -> 0.017118629 | AZ37: =+R41 -> 91.633787 | BA37: =+R42 -> 87.936295 | BB37: =+((AW37*24*AX37/100*$AV$36)*AY37*AZ37*BA37)/1000000 -> 26.080326 | BC37: =+BB37 -> 26.080326 | BE37: ST | BF37: =+AD38 -> 8502.7682 | BG37: =+AE38 -> 92.650689 | BH37: =+R39/10000 -> 0.017118629 | BI37: =+R41 -> 91.633787 | BJ37: =+R42 -> 87.936295 | BK37: =+R6*1000 -> 73.248003 | BL37: =+BM37*$BK$4+BK37 -> 99.197927 | BM37: =+((BF37*24*BG37/100*$BE$36)*BH37*BI37*BJ37)/1000000 -> 26.080326 | BN37: =+BL37 -> 99.197927
AC38: ST | AD38: =+R29 -> 8502.7682 | AE38: =+R32 -> 92.650689 | AF38: =+R34 -> 0.53544933 | AG38: =+R35 -> 90.294153 | AH38: =+((AD38*24*AE38/100*$AC$37)*AF38*AG38)/10000 -> 9598.1501 | AI38: =+AH38 -> 9598.1501 | AK38: Rendimiento | AL38: =+AL43 -> 8494.565 | AM38: =+AM37 -> 92.650689 | AN38: =+AN37 -> 0.53544933 | AO38: =+AO37 -> 90.294153 | AP38: =+AP37 -> -125.73242 | AQ38: =+AR38*$AQ$4+AP38 -> 9137.1354 | AR38: =+((AL38*24*AM38/100*$AC$37)*AN38*AO38)/10000 -> 9588.8901 | AS38: =+AQ38-AQ37 -> -8.9451575 | AV38: TPH | AW38: =+AW43 -> 8494.565 | AX38: =+AX37 -> 92.650689 | AY38: =+AY37 -> 0.017118629 | AZ38: =+AZ37 -> 91.633787 | BA38: =+BA37 -> 87.936295 | BB38: =+((AW38*24*AX38/100*$AV$36)*AY38*AZ38*BA38)/1000000 -> 26.055164 | BC38: =+BB38-BB37 -> -0.025161489 | BE38: Rendimiento | BF38: =+BF44 -> 8494.565 | BG38: =+BG37 -> 92.650689 | BH38: =+BH37 -> 0.017118629 | BI38: =+BI37 -> 91.633787 | BJ38: =+BJ37 -> 87.936295 | BK38: =+BK37 -> 73.248003 | BL38: =+BM38*$BK$4+BK38 -> 99.172892 | BM38: =+((BF38*24*BG38/100*$BE$36)*BH38*BI38*BJ38)/1000000 -> 26.055164 | BN38: =+BL38-BL37 -> -0.025035681
A39: Ley Alim. Mo | B39: ppm | C39: ='ST Original'!W39 -> 171.18629 | D39: ='ST Original'!#REF! -> #REF! | E39: =+C39-D39 -> #REF! | F39: =+E39/D39 -> #REF! | H39: Ley Alim. Mo | I39: ppm | J39: =C39 -> 171.18629 | K39: ='ST Original'!#REF! -> #REF! | L39: =+J39-K39 -> #REF! | M39: =+L39/K39 -> #REF! | O39: Ley Alim. Mo | P39: ppm | Q39: ='R+P'!$S$47 -> 192.88224 | R39: =C39 -> 171.18629 | S39: =+Q39-R39 -> 21.695952 | T39: =+S39/R39 -> 0.12673884 | V39: Ley Alim. Mo | W39: ppm | X39: =Real!R40 -> 209.05586 | Y39: ='ST Original'!$FR$39 -> 190.92613 | Z39: =+X39-Y39 -> 18.129727 | AA39: =+Z39/Y39 -> 0.09495676 | AC39: Rendimiento | AD39: =+AD43 -> 8494.565 | AE39: =+AE38 -> 92.650689 | AF39: =+AF38 -> 0.53544933 | AG39: =+AG38 -> 90.294153 | AH39: =+((AD39*24*AE39/100*$AC$37)*AF39*AG39)/10000 -> 9588.8901 | AI39: =+AH39-AH38 -> -9.2599974 | AK39: C.M. | AL39: =+AL43 -> 8494.565 | AM39: =+AM43 -> 92.32423 | AN39: =+AN37 -> 0.53544933 | AO39: =+AO37 -> 90.294153 | AP39: =+AP37 -> -125.73242 | AQ39: =+AR39*$AQ$4+AP39 -> 9104.4974 | AR39: =+((AL39*24*AM39/100*$AC$37)*AN39*AO39)/10000 -> 9555.1033 | AS39: =+AQ39-AQ38 -> -32.638084 | AV39: CM | AW39: =+AW43 -> 8494.565 | AX39: =+AX43 -> 92.32423 | AY39: =+AY37 -> 0.017118629 | AZ39: =+AZ37 -> 91.633787 | BA39: =+BA37 -> 87.936295 | BB39: =+((AW39*24*AX39/100*$AV$36)*AY39*AZ39*BA39)/1000000 -> 25.963358 | BC39: =+BB39-BB38 -> -0.091806408 | BE39: CM | BF39: =+BF44 -> 8494.565 | BG39: =+BG44 -> 92.32423 | BH39: =+BH37 -> 0.017118629 | BI39: =+BI37 -> 91.633787 | BJ39: =+BJ37 -> 87.936295 | BK39: =+BK37 -> 73.248003 | BL39: =+BM39*$BK$4+BK39 -> 99.081544 | BM39: =+((BF39*24*BG39/100*$BE$36)*BH39*BI39*BJ39)/1000000 -> 25.963358 | BN39: =+BL39-BL38 -> -0.091347376
A40: Rec. Mo Global | B40: % | C40: ='ST Original'!Z39 -> 80.579357 | D40: ='ST Original'!#REF! -> #REF! | E40: =+C40-D40 -> #REF! | F40: =+E40/D40 -> #REF! | H40: Rec. Mo Global | I40: % | J40: =C40 -> 80.579357 | K40: ='ST Original'!#REF! -> #REF! | L40: =+J40-K40 -> #REF! | M40: =+L40/K40 -> #REF! | O40: Rec. Mo Global | P40: % | Q40: ='R+P'!$V$47 -> 80.646505 | R40: =C40 -> 80.579357 | S40: =+Q40-R40 -> 0.067148601 | T40: =+S40/R40 -> 0.00083332262 | V40: Rec. Mo Global | W40: % | X40: =Real!U40 -> 81.170583 | Y40: ='ST Original'!$FU$39 -> 80.836534 | Z40: =+X40-Y40 -> 0.33404839 | AA40: =+Z40/Y40 -> 0.0041323938 | AC40: C.M. | AD40: =+AD43 -> 8494.565 | AE40: =+AE43 -> 92.32423 | AF40: =+AF38 -> 0.53544933 | AG40: =+AG38 -> 90.294153 | AH40: =+((AD40*24*AE40/100*$AC$37)*AF40*AG40)/10000 -> 9555.1033 | AI40: =+AH40-AH39 -> -33.786836 | AK40: Ley Cab. Cu,% | AL40: =+AL43 -> 8494.565 | AM40: =+AM43 -> 92.32423 | AN40: =+AN43 -> 0.51875622 | AO40: =+AO37 -> 90.294153 | AP40: =+AP37 -> -125.73242 | AQ40: =+AR40*$AQ$4+AP40 -> 8816.7367 | AR40: =+((AL40*24*AM40/100*$AC$37)*AN40*AO40)/10000 -> 9257.2144 | AS40: =+AQ40-AQ39 -> -287.76063 | AV40: Ley Mo | AW40: =+AW43 -> 8494.565 | AX40: =+AX43 -> 92.32423 | AY40: =+AY43 -> 0.019288224 | AZ40: =+AZ37 -> 91.633787 | BA40: =+BA37 -> 87.936295 | BB40: =+((AW40*24*AX40/100*$AV$36)*AY40*AZ40*BA40)/1000000 -> 29.253924 | BC40: =+BB40-BB39 -> 3.2905659 | BE40: Ley Mo | BF40: =+BF44 -> 8494.565 | BG40: =+BG44 -> 92.32423 | BH40: =+BH44 -> 0.019288224 | BI40: =+BI37 -> 91.633787 | BJ40: =+BJ37 -> 87.936295 | BK40: =+BK37 -> 73.248003 | BL40: =+BM40*$BK$4+BK40 -> 102.35566 | BM40: =+((BF40*24*BG40/100*$BE$36)*BH40*BI40*BJ40)/1000000 -> 29.253924 | BN40: =+BL40-BL39 -> 3.274113
A41: Rec. Mo Colectiva | B41: % | C41: ='ST Original'!X39 -> 91.633787 | D41: ='ST Original'!#REF! -> #REF! | E41: =+C41-D41 -> #REF! | F41: =+E41/D41 -> #REF! | H41: Rec. Mo Colectiva | I41: % | J41: =C41 -> 91.633787 | K41: ='ST Original'!#REF! -> #REF! | L41: =+J41-K41 -> #REF! | M41: =+L41/K41 -> #REF! | O41: Rec. Mo Colectiva | P41: % | Q41: ='R+P'!$T$47 -> 89.806766 | R41: =C41 -> 91.633787 | S41: =+Q41-R41 -> -1.8270206 | T41: =+S41/R41 -> -0.019938285 | V41: Rec. Mo Colectiva | W41: % | X41: =Real!S40 -> 89.313167 | Y41: ='ST Original'!$FS$39 -> 92.043617 | Z41: =+X41-Y41 -> -2.7304503 | AA41: =+Z41/Y41 -> -0.029664744 | AC41: Ley Cab. Cu,% | AD41: =+AD43 -> 8494.565 | AE41: =+AE43 -> 92.32423 | AF41: =+AF43 -> 0.51875622 | AG41: =+AG38 -> 90.294153 | AH41: =+((AD41*24*AE41/100*$AC$37)*AF41*AG41)/10000 -> 9257.2144 | AI41: =+AH41-AH40 -> -297.88885 | AK41: RCu, % | AL41: =+AL43 -> 8494.565 | AM41: =+AM43 -> 92.32423 | AN41: =+AN43 -> 0.51875622 | AO41: =+AO43 -> 90.397219 | AP41: =+AP37 -> -125.73242 | AQ41: =+AR41*$AQ$4+AP41 -> 8826.9441 | AR41: =+((AL41*24*AM41/100*$AC$37)*AN41*AO41)/10000 -> 9267.7811 | AS41: =+AQ41-AQ40 -> 10.207345 | AV41: RMoCol, % | AW41: =+AW43 -> 8494.565 | AX41: =+AX43 -> 92.32423 | AY41: =+AY43 -> 0.019288224 | AZ41: =+AZ43 -> 89.806766 | BA41: =+BA40 -> 87.936295 | BB41: =+((AW41*24*AX41/100*$AV$36)*AY41*AZ41*BA41)/1000000 -> 28.670651 | BC41: =+BB41-BB40 -> -0.58327307 | BE41: RMoCol, % | BF41: =+BF44 -> 8494.565 | BG41: =+BG44 -> 92.32423 | BH41: =+BH44 -> 0.019288224 | BI41: =+BI44 -> 89.806766 | BJ41: =+BJ40 -> 87.936295 | BK41: =+BK37 -> 73.248003 | BL41: =+BM41*$BK$4+BK41 -> 101.7753 | BM41: =+((BF41*24*BG41/100*$BE$36)*BH41*BI41*BJ41)/1000000 -> 28.670651 | BN41: =+BL41-BL40 -> -0.5803567
...

Sheet Acumulados
B1: 1000 | T1: 1000 | AY1: Inv. Final: | AZ1: 2968 | BA1: Tmf
D2: 30.5 | E2: 28 | F2: 31 | G2: 30 | H2: 31 | I2: 30 | J2: 31 | K2: 31 | L2: 30 | M2: 31 | N2: 31 | O2: 30 | P2: 31.5 | Q2: =SUM(D2:M2) -> 303.5 | R2: =+SUM(D2:P2) -> 396 | T2: 31 | U2: 28 | V2: 31 | W2: 30 | X2: 31 | Y2: 30 | Z2: 31 | AA2: 31 | AB2: 30 | AC2: 31 | AD2: 30 | AE2: 31 | AF2: =SUM(T2:AC4) -> 304 | AG2: =SUM(T2:AE4) -> 365
D3: =(D7-D8/0.9644)*1000 -> 431.13712 | E3: =(E7-E8/0.9644)*1000 -> 426.92697 | F3: =(F7-F8/0.9644)*1000 -> -281.44259 | G3: =(G7-G8/0.9644)*1000 -> 270.63574 | H3: =(H7-H8/0.9644)*1000 -> -588.20834 | I3: =(I7-I8/0.9644)*1000 -> 66.597659 | Q3: =(Q7-Q8/0.9644)*1000 -> 325.64656 | R3: =(R7-R8/0.9644)*1000 -> 792.21365 | T3: =(T7-T8/0.966)*1000 -> 2.8158809e-08 | U3: =(U7-U8/0.966)*1000 -> -1.6353141e-08 | V3: =(V7-V8/0.966)*1000 -> 1.5941026e-08 | W3: =(W7-W8/0.966)*1000 -> -3.932854e-09 | X3: =(X7-X8/0.966)*1000 -> -1.8015811e-08 | Y3: =(Y7-Y8/0.966)*1000 -> 4.3485215e-09 | AF3: =(AF7-AF8/0.966)*1000 -> 1.014655e-08 | AG3: =(AG7-AG8/0.966)*1000 -> 7.9296569e-08 | AQ3: ENERO | AS3: Rendimiento | AT3: CM % | AU3: Ley Cu | AV3: Rec Cu | AW3: CuFFP-CuFP | AX3: TMF | AY3: DIF
D4: =(D7*0.9644-D8)*1000 -> 415.78863 | E4: =(E7*0.9644-E8)*1000 -> 411.72837 | F4: =(F7*0.9644-F8)*1000 -> -271.42323 | G4: =(G7*0.9644-G8)*1000 -> 261.00111 | H4: =(H7*0.9644-H8)*1000 -> -567.26812 | I4: =(I7*0.9644-I8)*1000 -> 64.226783 | Q4: =(Q7*0.9644-Q8)*1000 -> 314.05354 | R4: =(R7*0.9644-R8)*1000 -> 764.01085 | T4: =(T7*0.966-T8)*1000 -> 2.7203129e-08 | U4: =(U7*0.966-U8)*1000 -> -1.5798918e-08 | V4: =(V7*0.966-V8)*1000 -> 1.5397461e-08 | W4: =(W7*0.966-W8)*1000 -> -3.7978509e-09 | X4: =(X7*0.966-X8)*1000 -> -1.7401192e-08 | Y4: =(Y7*0.966-Y8)*1000 -> 4.2028603e-09 | AF4: =(AF7*0.966-AF8)*1000 -> 9.8054898e-09 | AG4: =(AG7*0.966-AG8)*1000 -> 7.6624929e-08 | AQ4: BDGT Ajustado | AS4: =T14 -> 8278.1672 | AT4: =T18 -> 91.052835 | AU4: =T20 -> 0.47560795 | AV4: =T21 -> 89.520023 | AW4: =(T8-T7)*1000 -> -811.79957 | AX4: =AS4*AT4*24*30.5/100*AU4/100*AV4/100+AW4 -> 22679.554 | AY4: =AX4 -> 22679.554
D5: REAL | E5: REAL | F5: REAL | G5: REAL | H5: REAL | I5: REAL | J5: R+P | K5: R+P | M5: PM | Q5: Real | R5: R+P | T5: BD | U5: BD | V5: BD | W5: BD | X5: BD | Y5: BD | Z5: BD | AA5: R+P | AC5: PM | AI5: REAL | AL5: R+P
C6: Unidad | D6: BM Ene | E6: BM Feb | F6: BM Mar | G6: BM Abr | H6: BM May | I6: BM Jun | J6: BM Jul | K6: BM Ago | L6: BM Sep | M6: BM Sep | N6: BM Oct | O6: BM Nov | P6: R+P Dic | Q6: Acum. H1 | R6: Acum a Dic | T6: BD Ene | U6: BD Feb | V6: BD Mar | W6: BD Abr | X6: BD May | Y6: BD Jun | Z6: BD Jul | AA6: BD Ago | AB6: BD Sept | AC6: BD Oct | AD6: BD Nov | AE6: BD Dic | AF6: BD H1 | AG6: BD a Dic | AI6: DIF H1 | AJ6: % | AL6: DIF a Dic | AM6: % | AQ6: Rendimiento | AS6: =+$D$14 -> 8148.8879 | AT6: =AT4 -> 91.052835 | AU6: =AU4 -> 0.47560795 | AV6: =AV4 -> 89.520023 | AW6: =AW4 -> -811.79957 | AX6: =AS6*AT6*24*30.5/100*AU6/100*AV6/100+AW6 -> 22312.692 | AY6: =AX6-AX4 -> -366.86227
B7: Cu Fino Producido | C7: Kton | D7: 23.95399 | E7: 22.519131 | F7: 26.579021 | G7: 24.938046 | H7: 24.998531 | I7: 25.805466 | J7: 25.099591 | K7: 26.794658 | L7: 24.981376 | M7: 27.084518 | Q7: =SUM(D7:I7) -> 148.79418 | R7: =+SUM(D7:N7) -> 252.75433 | T7: 23.876458 | U7: 22.751614 | V7: 26.459281 | W7: 26.49665 | X7: 30.074574 | Y7: 29.481818 | Z7: 23.330845 | AA7: 25.162032 | AB7: 28.714162 | AC7: 29.087249 | AD7: 30.090002 | AF7: =SUM(T7:Y7) -> 159.14039 | AG7: =+SUM(T7:AE7) -> 295.52468 | AI7: =Q7-AF7 -> -10.34621 | AJ7: =AI7/AF7 -> -0.065013099 | AL7: =R7-AG7 -> -42.770356 | AM7: =AL7/AG7 -> -0.14472685 | AQ7: CM % | AS7: =AS6 -> 8148.8879 | AT7: =+$D$18 -> 88.463115 | AU7: =AU4 -> 0.47560795 | AV7: =AV4 -> 89.520023 | AW7: =AW4 -> -811.79957 | AX7: =AS7*AT7*24*30.5/100*AU7/100*AV7/100+AW7 -> 21654.986 | AY7: =AX7-AX6 -> -657.70573
B8: Cu Fino Filtrado Pagable | C8: Kton | D8: 22.685439 | E8: 21.305722 | F8: 25.904231 | G8: 23.789251 | H8: 24.675851 | I8: 24.822565 | J8: 24.240236 | K8: 22.126648 | L8: 26.613589 | M8: 26.828731 | Q8: =SUM(D8:I8) -> 143.18306 | R8: =+SUM(D8:N8) -> 242.99226 | T8: 23.064658 | U8: 21.978059 | V8: 25.559665 | W8: 25.595764 | X8: 29.052039 | Y8: 28.479436 | Z8: 22.537596 | AA8: 24.306523 | AB8: 27.73788 | AC8: 28.098282 | AD8: 29.066942 | AF8: =SUM(T8:Y8) -> 153.72962 | AG8: =+SUM(T8:AE8) -> 285.47684 | AI8: =Q8-AF8 -> -10.546563 | AJ8: =AI8/AF8 -> -0.068604627 | AL8: =R8-AG8 -> -42.484582 | AM8: =AL8/AG8 -> -0.14881971 | AO8: =G8-W8 -> -1.8065135 | AQ8: Ley Cu,% | AS8: =AS6 -> 8148.8879 | AT8: =AT7 -> 88.463115 | AU8: =+$D$20 -> 0.5130814 | AV8: =AV4 -> 89.520023 | AW8: =AW4 -> -811.79957 | AX8: =AS8*AT8*24*30.5/100*AU8/100*AV8/100+AW8 -> 23425.158 | AY8: =AX8-AX7 -> 1770.1721
B9: Mo Fino Producido | C9: Kton | D9: 0.6877459 | E9: 0.7682988 | F9: 0.7919837 | G9: 0.9899452 | H9: 1.2376732 | I9: 1.191114 | J9: 0.8455234 | K9: 1.0873835 | L9: 1.1182268 | M9: 1.3382371 | Q9: =SUM(D9:I9) -> 5.6667608 | R9: =+SUM(D9:N9) -> 10.056132 | T9: 0.8398606 | U9: 0.9127278 | V9: 0.9952153 | W9: 1.1689092 | X9: 1.1986114 | Y9: 1.2198837 | Z9: 0.824863 | AA9: 1.0567662 | AB9: 1.3598521 | AC9: 1.0812537 | AD9: 1.283036 | AF9: =SUM(T9:Y9) -> 6.335208 | AG9: =+SUM(T9:AE9) -> 11.940979 | AI9: =Q9-AF9 -> -0.6684472 | AJ9: =AI9/AF9 -> -0.10551306 | AL9: =R9-AG9 -> -1.8848474 | AM9: =AL9/AG9 -> -0.15784697 | AQ9: RCu, % | AS9: =AS6 -> 8148.8879 | AT9: =AT7 -> 88.463115 | AU9: =AU8 -> 0.5130814 | AV9: =+$D$21 -> 88.474775 | AW9: =AW4 -> -811.79957 | AX9: =AS9*AT9*24*30.5/100*AU9/100*AV9/100+AW9 -> 23142.164 | AY9: =AX9-AX8 -> -282.99418
B10: Mo Fino Envasado Pagable | C10: Kton | D10: 0.5593703 | E10: 0.7106961 | F10: 0.9812003 | G10: 1.0258433 | H10: 1.2090692 | I10: 1.2382653 | J10: 0.9370735 | K10: 0.9557617 | L10: 1.1409695 | M10: 1.1591302 | Q10: =SUM(D10:I10) -> 5.7244445 | R10: =+SUM(D10:N10) -> 9.9173794 | T10: 0.8356613 | U10: 0.9081641 | V10: 0.9902392 | W10: 1.1630647 | X10: 1.1926184 | Y10: 1.2137843 | Z10: 0.8207387 | AA10: 1.0514823 | AB10: 1.3530528 | AC10: 1.0758475 | AD10: 1.2766208 | AF10: =SUM(T10:Y10) -> 6.303532 | AG10: =+SUM(T10:AE10) -> 11.881274 | AI10: =Q10-AF10 -> -0.5790875 | AJ10: =AI10/AF10 -> -0.091867147 | AL10: =R10-AG10 -> -1.9638947 | AM10: =AL10/AG10 -> -0.16529328 | AQ10: Inventarios | AS10: =AS6 -> 8148.8879 | AT10: =AT7 -> 88.463115 | AU10: =AU8 -> 0.5130814 | AV10: =AV9 -> 88.474775 | AW10: =+($D$8-$D$7)*1000 -> -1268.5507 | AX10: =AS10*AT10*24*30.5/100*AU10/100*AV10/100+AW10 -> 22685.413 | AY10: =AX10-AX9 -> -456.7511
AQ11: Real | AS11: =AS6 -> 8148.8879 | AT11: =AT7 -> 88.463115 | AU11: =AU8 -> 0.5130814 | AV11: =AV9 -> 88.474775 | AW11: =AW10 -> -1268.5507 | AY11: =+SUM(AY4:AY10) -> 22685.413 | AZ11: =AY11-AY4 -> 5.8588405
B12: Tonelaje Procesado | C12: Kton | D12: 5276.8123 | E12: 4993.564 | F12: 5347.4708 | G12: 4979.3775 | H12: 5484.1979 | I12: 5118.1204 | J12: 4931.705 | K12: 5062.2333 | L12: 5101.3371 | M12: 5607.0996 | Q12: =SUM(D12:I12) -> 31199.543 | R12: =+SUM(D12:N12) -> 51901.918 | T12: 5607.9044 | U12: 5222.8705 | V12: 5115.5852 | W12: 5879.0851 | X12: 6219.2205 | Y12: 6022.8239 | Z12: 5113.1375 | AA12: 5314.0765 | AB12: 5878.2009 | AC12: 6213.1358 | AD12: 5781.6331 | AF12: =SUM(T12:Y12) -> 34067.49 | AG12: =+SUM(T12:AE12) -> 62367.674 | AI12: =Q12-AF12 -> -2867.9469 | AJ12: =AI12/AF12 -> -0.084184274 | AL12: =R12-AG12 -> -10465.756 | AM12: =AL12/AG12 -> -0.16780738 | AO12: =AP12-V12 -> 726.88744 | AP12: 5842.4727
B13: Toneladas por día | C13: Ktpd | D13: 170.21975 | E13: 178.34157 | F13: 172.49906 | G13: 165.97925 | H13: 176.90961 | I13: 170.60401 | J13: 159.08726 | K13: 163.29785 | L13: 169.48333 | M13: 180.87418 | Q13: =Q12/Q2 -> 102.79915 | R13: =R12/R2 -> 131.06545 | T13: 180.90014 | U13: 186.53109 | V13: 165.01888 | W13: 195.9695 | X13: 200.62002 | Y13: 200.7608 | Z13: 164.93992 | AA13: 171.42182 | AB13: 195.94003 | AC13: 200.42374 | AF13: =AF12/AF2 -> 112.06411 | AG13: =AG12/AG2 -> 170.87034 | AI13: =Q13-AF13 -> -9.2649583 | AJ13: =AI13/AF13 -> -0.082675517 | AL13: =R13-AG13 -> -39.804889 | AM13: =AL13/AG13 -> -0.23295377
B14: Rendimiento Global | C14: Tph | D14: 8148.8879 | E14: 8332.3276 | F14: 7997.1747 | G14: 8365.8896 | H14: 8204.964 | I14: 8016.3524 | J14: 8528.3777 | K14: 8383.8182 | L14: 7630.7967 | M14: 8036.6071 | Q14: =Q12*1000/(AF2*24*Q18/100) -> 8114.535 | R14: =R12*1000/(R2*24*R18/100) -> 8121.1153 | T14: 8278.1672 | U14: 8684.4809 | V14: 8745.2728 | W14: 8512.0482 | X14: 8702.6606 | Y14: 8750.6559 | Z14: 8432.7098 | AA14: 9072.7109 | AB14: 8628.0742 | AC14: 8684.6607 | AD14: 8236.0167 | AF14: =AF12*1000/(AF2*24*AF18/100) -> 8608.6106 | AG14: =AG12*1000/(R2*24*AG18/100) -> 9543.3215 | AI14: =Q14-AF14 -> -494.07564 | AJ14: =AI14/AF14 -> -0.057393191 | AL14: =R14-AG14 -> -1422.2062 | AM14: =AL14/AG14 -> -0.14902633
B15: AxB | C15: - | D15: 37.515527 | E15: 38.069277 | F15: 38.252026 | G15: 37.687322 | H15: 37.421213 | I15: 37.398726 | J15: 37.600247 | K15: 38.806704 | L15: 36.448042 | M15: 37.569619 | Q15: =SUMPRODUCT(D12:I12,D15:I15)/Q$12 -> 37.722068 | R15: =SUMPRODUCT($D$12:$M$12,D15:M15)/$R$12 -> 37.674591 | T15: 37.25541 | U15: 35.921331 | V15: 36.784395 | W15: 35.513843 | X15: 36.439688 | Y15: 35.694447 | Z15: 36.664253 | AA15: 36.916859 | AB15: 35.950088 | AC15: 37.69751 | AF15: =SUMPRODUCT(T12:Y12,T15:Y15)/AF$12 -> 36.254731 | AG15: =SUMPRODUCT($T$12:$AD$12,T15:AD15)/$AG$12 -> 33.09884 | AI15: =Q15-AF15 -> 1.4673369 | AJ15: =AI15/AF15 -> 0.040472977 | AL15: =R15-AG15 -> 4.5757513 | AM15: =AL15/AG15 -> 0.13824506 | AY15: Inv. Final: | AZ15: 3375.9215 | BA15: Tmf
B16: RQD | C16: - | D16: 78.042419 | E16: 80.745704 | F16: 81.84674 | G16: ='[18]TP sin BM'!F14 -> 85.465536 | H16: 85.465536 | I16: ='TP sin BM'!G14 -> 82.923534 | J16: 81.726664 | K16: 84.998951 | L16: 4.1336908 | M16: ='PM vs OL y BD'!D14 -> 82.923534 | Q16: =SUMPRODUCT(D$12:H$12,D16:H16)/Q$12 -> 68.814219 | R16: =SUMPRODUCT($D$12:$I$12,D16:I16)/$R$12 -> 49.543156 | T16: 80.669353 | U16: 86.227462 | V16: 86.384367 | W16: 89.675422 | X16: 89.877307 | Y16: 88.961175 | AF16: =SUMPRODUCT(T$12:X$12,T16:X16)/AF$12 -> 71.35318 | AG16: =SUMPRODUCT($D$12:$I$12,T16:Y16)/$R$12 -> 52.270592 | AI16: =Q16-AF16 -> -2.5389608 | AJ16: =AI16/AF16 -> -0.035583009 | AL16: =R16-AG16 -> -2.7274365 | AM16: =AL16/AG16 -> -0.052179177 | AQ16: FEBRERO | AS16: Rendimiento | AT16: CM % | AU16: Ley Cu | AV16: Rec Cu | AW16: CuFFP-CuFP | AX16: TMF | AY16: DIF
B17: F80 | C17: In | D17: 4.1622031 | E17: 4.25 | F17: 4.1451512 | G17: 4.21 | H17: 4.1 | I17: 4.27 | J17: 3.93 | K17: 4.04 | L17: 4.15 | M17: 4.1603619 | Q17: =SUMPRODUCT(D$12:I$12,D17:I17)/Q$12 -> 4.1877104 | R17: =SUMPRODUCT($D$12:$M$12,D17:M17)/$R$12 -> 4.142155 | T17: 4.0515644 | U17: 4.0481779 | V17: 4.0564913 | W17: 4.0004374 | X17: 4.029893 | Y17: 3.9363241 | Z17: 4.0151167 | AA17: 3.9721027 | AB17: 4.0573849 | AC17: 3.9664332 | AD17: 3.9527435 | AF17: =SUMPRODUCT(T$12:Y$12,T17:Y17)/AF$12 -> 4.0186323 | AG17: =SUMPRODUCT($T$12:$AD$12,T17:AD17)/$AG$12 -> 4.0067238 | AI17: =Q17-AF17 -> 0.16907814 | AJ17: =AI17/AF17 -> 0.042073553 | AL17: =R17-AG17 -> 0.13543119 | AM17: =AL17/AG17 -> 0.033800981 | AQ17: BDGT Ajustado | AS17: =U14 -> 8684.4809 | AT17: =U18 -> 89.494455 | AU17: =U20 -> 0.4844022 | AV17: =U21 -> 89.928394 | AW17: =(U8-U7)*1000 -> -773.55487 | AX17: =AS17*AT17*24*28/100*AU17/100*AV17/100+AW17 -> 21978.059 | AY17: =AX17 -> 21978.059
B18: CM Global | C18: % | D18: 88.463115 | E18: 93.369271 | F18: 89.875 | G18: 82.552011 | H18: 89.83871 | I18: 88.675 | J18: 77.724462 | K18: 81.157258 | L18: 92.543488 | M18: 93.776193 | Q18: =SUMPRODUCT(D2:I2,D18:I18)/AF2 -> 52.698684 | R18: =(D2*24*D18+E2*24*E18+F2*24*F18+G2*24*G18+H2*24*H18+I2*24*I18+J2*24*J18+K2*24*K18+M2*24*M18+L2*L18*24+N2*24*N18)/(R2*24) -> 67.245202 | T18: 91.052835 | U18: 89.494455 | V18: 78.622894 | W18: 95.927511 | X18: 96.053008 | Y18: 95.593214 | Z18: 81.49808 | AA18: 78.725928 | AB18: 94.623292 | AC18: 96.157919 | AD18: 97.499147 | AF18: =SUMPRODUCT(T2:Y2,T18:Y18)/AF2 -> 54.24032 | AG18: =(D2*24*T18+U2*24*U18+V2*24*V18+W2*24*W18+X2*24*X18+Y2*24*Y18+Z2*24*Z18+AA2*24*AA18+AC2*24*AC18+AB2*24*AB18)/(R2*24) -> 68.762802 | AI18: =Q18-AF18 -> -1.5416363 | AJ18: =AI18/AF18 -> -0.028422331 | AL18: =R18-AG18 -> -1.5175999 | AM18: =AL18/AG18 -> -0.022070071 | AO18: =AO12*F20*F21/10000*1000 -> 3615.0991 | AP18: =AO18*0.9644 -> 3486.4016 | AQ18: Rendimiento | AS18: =+$E$14 -> 8332.3276 | AT18: =AT17 -> 89.494455 | AU18: =AU17 -> 0.4844022 | AV18: =AV17 -> 89.928394 | AW18: =AW17 -> -773.55487 | AX18: =AS18*AT18*24*28/100*AU18/100*AV18/100+AW18 -> 21055.487 | AY18: =AX18-AX17 -> -922.57144
AO19: Aporte flujo cero | AQ19: CM % | AS19: =AS18 -> 8332.3276 | AT19: =+$E$18 -> 93.369271 | AU19: =AU17 -> 0.4844022 | AV19: =AV17 -> 89.928394 | AW19: =AW17 -> -773.55487 | AX19: =AS19*AT19*24*28/100*AU19/100*AV19/100+AW19 -> 22000.613 | AY19: =AX19-AX18 -> 945.12583
B20: Ley Alim. Cu | C20: % | D20: 0.5130814 | E20: 0.5236813 | F20: 0.5518866 | G20: 0.5593653 | H20: 0.5117386 | I20: 0.5527667 | J20: 0.5629039 | K20: 0.5796008 | L20: 0.5364302 | M20: 0.53164717 | Q20: =SUMPRODUCT(D$12:I$12,D20:I20)/Q$12 -> 0.53508993 | R20: =SUMPRODUCT($D$12:$M$12,D20:M20)/$R$12 -> 0.54183395 | T20: 0.47560795 | U20: 0.4844022 | V20: 0.57638134 | W20: 0.49662714 | X20: 0.53934664 | Y20: 0.54510952 | Z20: 0.50293145 | AA20: 0.5307765 | AB20: 0.54398213 | AC20: 0.52332063 | AD20: 0.58348174 | AF20: =SUMPRODUCT(T$12:Y$12,T20:Y20)/AF$12 -> 0.5196388 | AG20: =SUMPRODUCT($T$12:$AD$12,T20:AD20)/$AG$12 -> 0.52779762 | AI20: =Q20-AF20 -> 0.015451127 | AJ20: =AI20/AF20 -> 0.029734359 | AL20: =R20-AG20 -> 0.014036333 | AM20: =AL20/AG20 -> 0.026594157 | AQ20: Ley Cu,% | AS20: =AS18 -> 8332.3276 | AT20: =AT19 -> 93.369271 | AU20: =+$E$20 -> 0.5236813 | AV20: =AV17 -> 89.928394 | AW20: =AW17 -> -773.55487 | AX20: =AS20*AT20*24*28/100*AU20/100*AV20/100+AW20 -> 23847.32 | AY20: =AX20-AX19 -> 1846.7067
B21: Rec. Cu | C21: % | D21: 88.474775 | E21: 86.11153 | F21: 90.116266 | G21: 89.308562 | H21: 89.057102 | I21: 91.0301 | J21: 90.257233 | K21: 91.257921 | L21: 91.270096 | M21: 90.857196 | Q21: =Q7/(Q12*Q20/100)*100 -> 89.127342 | R21: =R7/(R12*R20/100)*100 -> 89.877085 | T21: 89.520023 | U21: 89.928394 | V21: 89.737258 | W21: 90.750864 | X21: 89.659343 | Y21: 89.798757 | Z21: 90.726507 | AA21: 89.208497 | AB21: 89.798087 | AC21: 89.45898 | AD21: =+AD7/(AD12*AD20%)*100 -> 89.195802 | AF21: =AF7/(AF12*AF20/100)*100 -> 89.89566 | AG21: =AG7/(AG12*AG20/100)*100 -> 89.777351 | AI21: =Q21-AF21 -> -0.76831883 | AJ21: =AI21/AF21 -> -0.0085467845 | AL21: =R21-AG21 -> 0.099733533 | AM21: =AL21/AG21 -> 0.0011108986 | AQ21: RCu, % | AS21: =AS18 -> 8332.3276 | AT21: =AT19 -> 93.369271 | AU21: =AU20 -> 0.5236813 | AV21: =+$E$21 -> 86.11153 | AW21: =AW17 -> -773.55487 | AX21: =AS21*AT21*24*28/100*AU21/100*AV21/100+AW21 -> 22802.327 | AY21: =AX21-AX20 -> -1044.9929
B22: Conc Cu Producido | C22: Kton | D22: 90.493144 | E22: 83.847982 | F22: 99.042431 | G22: 89.566273 | H22: 93.007885 | I22: 89.551669 | J22: 92.499418 | K22: 95.244432 | L22: 91.600563 | M22: 96.822295 | Q22: =SUM(D22:I22) -> 545.50938 | R22: =+SUM(D22:N22) -> 921.67609 | T22: 89.110927 | U22: 84.171301 | V22: 90.892581 | W22: 92.263072 | X22: 101.86319 | Y22: 103.56013 | Z22: 76.758648 | AA22: 81.551769 | AB22: 94.318199 | AC22: 97.434661 | AD22: =+AD7/AD23% -> 98.533999 | AF22: =SUM(T22:Y22) -> 561.8612 | AG22: =+SUM(T22:AE22) -> 1010.4585 | AI22: =Q22-AF22 -> -16.351817 | AJ22: =AI22/AF22 -> -0.029102948 | AL22: =R22-AG22 -> -88.782386 | AM22: =AL22/AG22 -> -0.087863468 | AQ22: Inventarios | AS22: =AS18 -> 8332.3276 | AT22: =AT19 -> 93.369271 | AU22: =AU20 -> 0.5236813 | AV22: =AV21 -> 86.11153 | AW22: =+($E$8-$E$7)*1000 -> -1213.4094 | AX22: =AS22*AT22*24*28/100*AU22/100*AV22/100+AW22 -> 22362.473 | AY22: =AX22-AX21 -> -439.85457
B23: Ley Conc. Cu | C23: % | D23: 26.470502 | E23: 26.857094 | F23: 26.835994 | G23: 27.779301 | H23: 26.877862 | I23: 28.76172 | J23: 27.082185 | K23: 28.097974 | L23: 27.272077 | M23: 27.973431 | Q23: =Q7/Q22*100 -> 27.276192 | R23: =R7/R22*100 -> 27.423336 | T23: 26.794085 | U23: 27.030132 | V23: 29.110496 | W23: 28.718587 | X23: 29.524478 | Y23: 28.468308 | Z23: 30.39507 | AA23: 30.85406 | AB23: 30.443925 | AC23: 29.853081 | AD23: 30.537685 | AF23: =AF7/AF22*100 -> 28.323791 | AG23: =AG7/AG22*100 -> 29.246594 | AI23: =Q23-AF23 -> -1.0475999 | AJ23: =AI23/AF23 -> -0.036986569 | AL23: =R23-AG23 -> -1.823258 | AM23: =AL23/AG23 -> -0.062340865 | AQ23: Real | AS23: =AS18 -> 8332.3276 | AT23: =AT19 -> 93.369271 | AU23: =AU20 -> 0.5236813 | AV23: =AV21 -> 86.11153 | AW23: =AW22 -> -1213.4094 | AY23: =+SUM(AY17:AY22) -> 22362.473 | AZ23: =AY23-AY17 -> 384.41364
B25: Ley Alim. Mo | C25: ppm | D25: 174.76501 | E25: 199.16807 | F25: 196.46034 | G25: 241.18259 | H25: 263.90326 | I25: 280.52512 | J25: 209.4622 | K25: 256.88781 | L25: 273.14672 | M25: 282.80736 | Q25: =SUMPRODUCT(D$12:I$12,D25:I25)/Q$12 -> 226.00731 | R25: =SUMPRODUCT($D$12:$N$12,D25:N25)/$R$12 -> 238.21661 | T25: 179.78398 | U25: 209.52561 | V25: 231.98672 | W25: 236.94845 | X25: 229.03083 | Y25: 240.44486 | Z25: 194.46641 | AA25: 235.97812 | AB25: 278.22511 | AC25: 208.13685 | AD25: 267.45959 | AF25: =SUMPRODUCT(T$12:Y$12,T25:Y25)/AF$12 -> 221.762 | AG25: =SUMPRODUCT($T$12:$AD$12,T25:AD25)/$AG$12 -> 228.93611 | AI25: =Q25-AF25 -> 4.2453123 | AJ25: =AI25/AF25 -> 0.019143552 | AL25: =R25-AG25 -> 9.2805015 | AM25: =AL25/AG25 -> 0.040537517
B26: Rec. Mo Global | C26: % | D26: 74.576476 | E26: 77.250234 | F26: 75.386387 | G26: 82.430917 | H26: 85.516143 | I26: 82.960449 | J26: 81.850793 | K26: 83.617485 | L26: 80.250897 | M26: 84.392546 | Q26: =Q9/(Q12*Q25)*100000000 -> 80.364484 | R26: =R9/(R12*R25)*100000000 -> 81.33463 | T26: 83.302041 | U26: 83.405539 | V26: 83.860718 | W26: 83.910666 | X26: 84.148913 | Y26: 84.236979 | Z26: 82.956376 | AA26: 84.271235 | AB26: 84.407831 | AC26: 83.611843 | AD26: =+AD9/(AD12*AD25*10^-8) -> 82.971728 | AF26: =AF9/(AF12*AF25)*100000000 -> 83.855898 | AG26: =AG9/(AG12*AG25)*100000000 -> 83.630768 | AI26: =Q26-AF26 -> -3.4914143 | AJ26: =AI26/AF26 -> -0.041635882 | AL26: =R26-AG26 -> -2.2961383 | AM26: =AL26/AG26 -> -0.027455664
B27: Conc Mo Producido | C27: ton | D27: 1.0760145 | E27: 1.3516964 | F27: 1.9218213 | G27: 1.9635255 | H27: 2.2737817 | I27: 2.2828355 | J27: 1.7455797 | K27: 1.8177446 | L27: 2.1524625 | M27: 2.5823875 | Q27: =SUM(D27:I27) -> 10.869675 | R27: =+SUM(D27:N27) -> 19.167849 | T27: 1.5552975 | U27: 1.6902366 | V27: 1.8429912 | W27: 2.1646466 | X27: 2.2196507 | Y27: 2.2590439 | Z27: 1.5275241 | AA27: 1.9569744 | AB27: 2.5148056 | AC27: 2.0023217 | AF27: =SUM(T27:Y27) -> 11.731867 | AG27: =+SUM(T27:AE27) -> 19.733492 | AI27: =Q27-AF27 -> -0.8621917 | AJ27: =AI27/AF27 -> -0.073491434 | AL27: =R27-AG27 -> -0.56564313 | AM27: =AL27/AG27 -> -0.028664117
B28: As Alim. | C28: ppm | D28: 26.762132 | E28: 62.305812 | F28: 70.909227 | G28: ='[18]TP sin BM'!F26 -> 29.442452 | H28: ='[18]TP sin BM'!F26 -> 29.442452 | I28: 33.650043 | Q28: =SUMPRODUCT(D$12:H$12,D28:H28)/Q$12 -> 36.526341 | R28: =SUMPRODUCT($D$12:$I$12,D28:I28)/$R$12 -> 25.275176 | T28: 37.982096 | U28: 26.012162 | V28: 39.398148 | W28: 19.755106 | X28: 34.418888 | Y28: 37.982096 | AF28: =SUMPRODUCT(T$12:X$12,T28:X28)/AF$12 -> 25.848788 | AG28: =SUMPRODUCT($T$12:$Y$12,T28:Y28)/$AG$12 -> 17.787465 | AI28: =Q28-AF28 -> 10.677554 | AJ28: =AI28/AF28 -> 0.41307754 | AL28: =R28-AG28 -> 7.4877116 | AM28: =AL28/AG28 -> 0.42095441 | AY28: Inv. Final: | AZ28: 3105
B29: As Conc. | C29: ppm | D29: 1684.0909 | E29: 2118.3123 | F29: 1608.4598 | G29: ='[18]TP sin BM'!F27 -> 1304.1798 | H29: ='[18]TP sin BM'!F27 -> 1304.1798 | I29: 1346.0017 | Q29: =SUMPRODUCT(D$22:H$22,D29:H29)/Q$22 -> 1333.4879 | R29: =SUMPRODUCT($D$22:$I$22,D29:I29)/$R$22 -> 920.02699 | T29: 1521.919 | U29: 1040.4865 | V29: 1575.9259 | W29: 780.83285 | X29: 1376.6955 | Y29: 1519.2838 | AF29: =SUMPRODUCT(T$22:X$22,T29:X29)/AF$22 -> 1029.9969 | AG29: =SUMPRODUCT($T$22:$Y$22,T29:Y29)/$AG$22 -> 728.43423 | AI29: =Q29-AF29 -> 303.491 | AJ29: =AI29/AF29 -> 0.29465234 | AL29: =R29-AG29 -> 191.59275 | AM29: =AL29/AG29 -> 0.26301997 | AQ29: MARZO | AS29: Rendimiento | AT29: CM % | AU29: Ley Cu | AV29: Rec Cu | AW29: CuFFP-CuFP | AX29: TMF | AY29: DIF
B31: Pagabilidad | D31: =D8/D32 -> 0.96229821 | E31: =E8/E32 -> 0.96358083 | F31: =F8/F32 -> 0.96420839 | G31: =G8/G32 -> 0.9635875 | H31: =H8/H32 -> 0.96293895 | I31: =I8/I32 -> 0.9649746 | J31: =J8/J32 -> 0.96528417 | K31: 0.9644 | L31: 0.9644 | M31: 0.9644 | N31: 0.9644 | Q31: =Q8/Q32 -> 0.9636225 | R31: =R8/R32 -> 0.96402975 | T31: 0.966 | U31: 0.966 | V31: 0.966 | W31: 0.966 | X31: 0.966 | Y31: 0.966 | Z31: 0.966 | AA31: 0.966 | AB31: 0.966 | AC31: 0.966 | AD31: 0.966 | AE31: 0.966 | AF31: =AF8/AF32 -> 0.966 | AG31: =AG8/AG32 -> 0.966 | AQ31: BDGT Ajustado | AS31: =V14 -> 8745.2728 | AT31: =V18 -> 78.622894 | AU31: =V20 -> 0.57638134 | AV31: =V21 -> 89.737258 | AW31: =(V8-V7)*1000 -> -899.61556 | AX31: =AS31*AT31*24*$V$2/100*AU31/100*AV31/100+AW31 -> 25559.665 | AY31: =AX31 -> 25559.665
B32: Cu Filtrado | D32: 23.57423 | E32: 22.110986 | F32: 26.865801 | G32: 24.68821 | H32: 25.625562 | I32: 25.723542 | J32: 25.112021 | K32: =K8/K31 -> 22.943435 | L32: =L8/L31 -> 27.596007 | M32: =M8/M31 -> 27.81909 | N32: =N8/N31 -> 0 | Q32: =SUM(D32:I32) -> 148.58833 | R32: =SUM(D32:M32) -> 252.05888 | T32: =T8/T31 -> 23.876458 | U32: =U8/U31 -> 22.751614 | V32: =V8/V31 -> 26.459281 | W32: =W8/W31 -> 26.49665 | X32: =X8/X31 -> 30.074574 | Y32: =Y8/Y31 -> 29.481818 | Z32: =Z8/Z31 -> 23.330845 | AA32: =AA8/AA31 -> 25.162032 | ... AE32: =AE8/AE31 -> 0 | AF32: =SUM(T32:Y32) -> 159.14039 | AG32: =+SUM(T32:AE32) -> 295.52468 | AQ32: Rendimiento | AS32: =+$F$14 -> 7997.1747 | AT32: =AT31 -> 78.622894 | AU32: =AU31 -> 0.57638134 | AV32: =AV31 -> 89.737258 | AW32: =AW31 -> -899.61556 | AX32: =AS32*AT32*24*$V$2/100*AU32/100*AV32/100+AW32 -> 23296.255 | AY32: =AX32-AX31 -> -2263.41
AQ33: CM % | AS33: =AS32 -> 7997.1747 | AT33: =+$F$18 -> 89.875 | AU33: =AU31 -> 0.57638134 | AV33: =AV31 -> 89.737258 | AW33: =AW31 -> -899.61556 | AX33: =AS33*AT33*24*$V$2/100*AU33/100*AV33/100+AW33 -> 26759.044 | AY33: =AX33-AX32 -> 3462.789
L34: =+L17*25.4 -> 105.41 | AQ34: Ley Cu,% | AS34: =AS32 -> 7997.1747 | AT34: =AT33 -> 89.875 | AU34: =+$F$20 -> 0.5518866 | AV34: =AV31 -> 89.737258 | AW34: =AW31 -> -899.61556 | AX34: =AS34*AT34*24*$V$2/100*AU34/100*AV34/100+AW34 -> 25583.622 | AY34: =AX34-AX33 -> -1175.4228
AQ35: RCu, % | AS35: =AS32 -> 7997.1747 | AT35: =AT33 -> 89.875 | AU35: =AU34 -> 0.5518866 | AV35: =+$F$21 -> 90.116266 | AW35: =AW31 -> -899.61556 | AX35: =AS35*AT35*24*$V$2/100*AU35/100*AV35/100+AW35 -> 25695.474 | AY35: =AX35-AX34 -> 111.85269
C36: Rend | D36: CM | E36: Ley | F36: Rec | G36: Inv | H36: Pag | I36: Fino | J36: DIF | AQ36: Inventarios | AS36: =AS32 -> 7997.1747 | AT36: =AT33 -> 89.875 | AU36: =AU34 -> 0.5518866 | AV36: =AV35 -> 90.116266 | AW36: =+($F$8-$F$7)*1000 -> -674.78991 | AX36: =AS36*AT36*24*$V$2/100*AU36/100*AV36/100+AW36 -> 25920.3 | AY36: =AX36-AX35 -> 224.82564
B37: BDGT H1 | C37: =AF14 -> 8608.6106 | D37: =AF18 -> 54.24032 | E37: =AF20 -> 0.5196388 | F37: =AF21 -> 89.89566 | G37: =(AF8/$AF$31-AF7)*1000 -> -1.0174972e-08 | H37: =AF31 -> 0.966 | I37: =(C37*$AF$2*24*D37/100*E37/100*F37/100+G37)*H37 -> 153729.62 | J37: =I37 -> 153729.62 | AA37: =(C37*$AF$2*24*D37/100)/1000 -> 34067.49 | AG37: TMS | AO37: Real | AQ37: =AS32 -> 7997.1747 | AR37: =AT33 -> 89.875 | AS37: =AU34 -> 0.5518866 | AT37: =AV35 -> 90.116266 | AU37: =AW36 -> -674.78991 | AW37: =+SUM(AY31:AY36) -> 25920.3 | AX37: =AW37-AY31 -> 360.63446
B38: Rendimiento | C38: =Q14 -> 8114.535 | D38: =D37 -> 54.24032 | E38: =E37 -> 0.5196388 | F38: =F37 -> 89.89566 | G38: =G37 -> -1.0174972e-08 | H38: =H37 -> 0.966 | I38: =(C38*$AF$2*24*D38/100*E38/100*F38/100+G38)*H38 -> 144906.59 | J38: =I38-I37 -> -8823.0336 | AA38: =(C38*$AF$2*24*D38/100)/1000 -> 32112.248 | AG38: =AA38-AA37 -> -1955.242 | AH38: Rendimiento
B39: CM | C39: =C38 -> 8114.535 | D39: =Q18 -> 52.698684 | E39: =E38 -> 0.5196388 | F39: =F38 -> 89.89566 | G39: =G38 -> -1.0174972e-08 | H39: =H38 -> 0.966 | I39: =(C39*$AF$2*24*D39/100*E39/100*F39/100+G39)*H39 -> 140788 | J39: =I39-I38 -> -4118.583 | K39: =J39+J38 -> -12941.617 | AA39: =(C39*$AF$2*24*D39/100)/1000 -> 31199.543 | AG39: =AA39-AA38 -> -912.70494 | AH39: CM
B40: Ley | C40: =C39 -> 8114.535 | D40: =D39 -> 52.698684 | E40: =Q20 -> 0.53508993 | F40: =F39 -> 89.89566 | G40: =G39 -> -1.0174972e-08 | H40: =H39 -> 0.966 | I40: =(C40*$AF$2*24*D40/100*E40/100*F40/100+G40)*H40 -> 144974.25 | J40: =I40-I39 -> 4186.2411
B41: Rec Cu | C41: =C40 -> 8114.535 | D41: =D40 -> 52.698684 | E41: =E40 -> 0.53508993 | F41: =Q21 -> 89.127342 | G41: =G40 -> -1.0174972e-08 | H41: =H40 -> 0.966 | I41: =(C41*$AF$2*24*D41/100*E41/100*F41/100+G41)*H41 -> 143735.18 | J41: =I41-I40 -> -1239.0636
B42: Inv. | C42: =C41 -> 8114.535 | D42: =D41 -> 52.698684 | E42: =E40 -> 0.53508993 | F42: =F41 -> 89.127342 | G42: =(Q8/Q31-Q7)*1000 -> -205.85478 | H42: =H41 -> 0.966 | I42: =(C42*$AF$2*24*D42/100*E42/100*F42/100+G42)*H42 -> 143536.33 | J42: =I42-I41 -> -198.85572
...

